Workbook

Sheet Summary
A1: Tranched Debt Sizing: Summary
A2: 150 MW solar PV, illustrative inputs. All figures in $mm unless stated. Change blue cells on the Inputs tab.
A4: Sources of funds | B4: $mm | C4: % of total | D4: Rate | E4: Tenor (yrs) | F4: Sizing constraint
A5: Tranche A: Senior term loan | B5: =Model!C30 -> 136.99149 | C5: =IF($B$9>0,B5/$B$9,0) -> 0.78280851 | D5: =Inputs!B25 -> 0.065 | E5: =Inputs!B24 -> 18 | F5: =Model!C31 -> DSCR
A6: Tranche B: Mezzanine loan | B6: =Model!C41 -> 11.75851 | C6: =IF($B$9>0,B6/$B$9,0) -> 0.067191488 | D6: =Inputs!B31 -> 0.1 | E6: =Inputs!B30 -> 18 | F6: =Model!C42 -> Gearing
A7: Sponsor equity | B7: =B9-B5-B6 -> 26.25 | C7: =IF($B$9>0,B7/$B$9,0) -> 0.15 | F7: Plug
A8: Total debt | B8: =B5+B6 -> 148.75 | C8: =IF($B$9>0,B8/$B$9,0) -> 0.85
A9: Total sources | B9: =Inputs!B19 -> 175 | C9: =SUM(C5:C7) -> 1
A11: Uses of funds | B11: $mm | C11: % of total
A12: EPC + development costs | B12: =Inputs!B17 -> 165 | C12: =IF($B$14>0,B12/$B$14,0) -> 0.94285714
A13: Financing fees + IDC | B13: =Inputs!B18 -> 10 | C13: =IF($B$14>0,B13/$B$14,0) -> 0.057142857
A14: Total uses | B14: =B12+B13 -> 175 | C14: =IF($B$14>0,B14/$B$14,0) -> 1
A16: Key credit metrics (P50 unless stated) | B16: Value
A17: Senior: minimum DSCR (P50) | B17: =MIN(Model!E52:AC52) -> 1.3379787
A18: Senior: average DSCR (P50) | B18: =AVERAGE(Model!E52:AC52) -> 1.3422581
A19: Senior: minimum DSCR (P90) | B19: =MIN(Model!E53:AC53) -> 1.2
A20: Senior: LLCR at close (P50) | B20: =IF(Model!C30>0,SUMPRODUCT(Model!E21:AC21,Model!E6:AC6,1/(1+Inputs!B25)^Model!E$4:AC$4)/Model!C30,0) -> 1.3415621
A21: Senior: weighted average life (yrs) | B21: =IF(Model!C30>0,SUMPRODUCT(Model!E50:AC50,Model!E$4:AC$4)/Model!C30,0) -> 11.661333
A22: Combined: minimum DSCR (P50) | B22: =MIN(Model!E61:AC61) -> 1.2052063
A23: Combined: minimum DSCR (P90) | B23: =MIN(Model!E62:AC62) -> 1.0809197
A24: Mezz: weighted average life (yrs) | B24: =IF(Model!C41>0,SUMPRODUCT(Model!E59:AC59,Model!E$4:AC$4)/Model!C41,0) -> 12.563338
A25: Project IRR (unlevered, post-tax) | B25: =IRR(Model!D65:AC65) -> 0.089137174
A26: Equity IRR (post-tax, P50) | B26: =IRR(Model!D66:AC66,0.15) -> 0.14315796
A27: Equity multiple (MOIC) | B27: =IF(Model!D66<0,SUM(Model!E66:AC66)/-Model!D66,0) -> 7.2429205
A29: Integrity checks | B29: Value | C29: Status
A30: Senior balance at maturity | B30: =INDEX(Model!E51:AC51,Inputs!B24) -> 2.1316282e-13 | C30: =IF(ABS(B30)<0.001,"OK","CHECK") -> OK
A31: Mezz balance at maturity | B31: =INDEX(Model!E60:AC60,Inputs!B30) -> -3.8635761e-14 | C31: =IF(ABS(B31)<0.001,"OK","CHECK") -> OK
A32: Sources less uses | B32: =B9-B14 -> 0 | C32: =IF(ABS(B32)<0.001,"OK","CHECK") -> OK
A33: Minimum senior principal (no negative amortization) | B33: =MIN(Model!E50:AC50) -> -2.0217268e-14 | C33: =IF(B33>=-0.001,"OK","CHECK") -> OK
A34: Minimum mezz principal (no negative amortization) | B34: =MIN(Model!E59:AC59) -> 3.8635761e-15 | C34: =IF(B34>=-0.001,"OK","CHECK") -> OK
A36: Structuring notes
A37: 1. Senior debt service is sculpted to the lower of CFADS/1.30x (P50) and CFADS/1.20x (P90) over its tenor; debt = PV of that profile at the all-in rate, capped at max gearing.
A38: 2. If gearing binds, the sculpted profile is scaled down pro rata so the loan still fully amortizes at maturity (actual DSCRs rise above target).
A39: 3. Mezz sizes on combined DSCR floors (1.15x P50 / 1.05x P90) and takes the residual DS capacity after senior. If mezz tenor exceeds senior, most of its capacity sits in the tail and early years can turn into PIK accretion (flagged by the integrity check).
A40: 4. Simplifications: annual periods, no construction-period drawdown profile, no DSRA/MRA, no cash sweep, no interest tax shield. Fees/IDC held fixed to stay non-circular.

Sheet Inputs
A1: Inputs: 150 MW Solar PV Project (Illustrative)
A2: Legend: blue = hardcoded input (edit these) | yellow fill = key sizing levers | black = formula. All values are illustrative placeholders, not market quotes.
A3: Item | B3: Value | C3: Unit | D3: Source / note
A4: Project
A5: Installed capacity | B5: 150 | C5: MW | D5: Illustrative
A6: P50 net capacity factor | B6: 0.24 | C6: % | D6: Illustrative; replace with independent energy yield report
A7: P90 (1-year) net capacity factor | B7: 0.215 | C7: % | D7: Illustrative; replace with independent energy yield report
A8: Annual module degradation | B8: 0.005 | C8: % | D8: Illustrative
A9: Operating life | B9: 25 | C9: years | D9: Model horizon from COD
A10: Revenue
A11: PPA tariff (Year 1) | B11: 68 | C11: $/MWh | D11: Illustrative
A12: Tariff escalation | B12: 0.02 | C12: % p.a. | D12: Illustrative
A13: Operating costs
A14: Fixed O&M + SG&A (Year 1) | B14: 18 | C14: $/kW-yr | D14: Illustrative
A15: Opex escalation | B15: 0.025 | C15: % p.a. | D15: Illustrative
A16: Project cost
A17: EPC + development costs | B17: 165 | C17: $mm | D17: Illustrative
A18: Financing fees + IDC (estimate) | B18: 10 | C18: $mm | D18: Held fixed to avoid a circular reference; true-up in a full model
A19: Total project cost | B19: =B17+B18 -> 175 | C19: $mm | D19: Formula
A20: Tax
A21: Corporate tax rate | B21: 0.25 | C21: % | D21: Illustrative
A22: Tax depreciation life (straight line) | B22: 20 | C22: years | D22: Interest tax shield excluded (conservative, avoids circularity)
A23: Senior term loan (Tranche A)
A24: Tenor from COD | B24: 18 | C24: years | D24: Illustrative
A25: All-in interest rate (base + margin + swap) | B25: 0.065 | C25: % p.a. | D25: Illustrative; fixed via swap
A26: Target DSCR: P50 case | B26: 1.3 | C26: x | D26: Senior sculpting target, P50
A27: Target DSCR: P90 case | B27: 1.2 | C27: x | D27: Senior sculpting target, P90 (1-yr)
A28: Max senior gearing | B28: 0.8 | C28: % of cost | D28: Senior debt / total project cost cap
A29: Mezzanine / HoldCo loan (Tranche B)
A30: Tenor from COD | B30: 18 | C30: years | D30: Coterminous with senior; a longer tenor pushes repayment into the post-senior tail (see Summary note 3)
A31: All-in interest rate | B31: 0.1 | C31: % p.a. | D31: Illustrative
A32: Combined DSCR floor: P50 case | B32: 1.15 | C32: x | D32: Senior + mezz debt service
A33: Combined DSCR floor: P90 case | B33: 1.05 | C33: x | D33: Senior + mezz debt service
A34: Max total gearing | B34: 0.85 | C34: % of cost | D34: (Senior + mezz) / total project cost cap

Sheet Model
A1: Tranched Debt Sizing Model: Annual ($mm unless stated)
A2: Sizing: each tranche is sculpted to the LOWER of its P50 and P90 DSCR targets, then capped by gearing. Mezz sizes on combined DSCR and takes the residual capacity after senior.
A4: Line item | B4: Unit | C4: Total / value | D4: 0 | E4: =D4+1 -> 1 | F4: =E4+1 -> 2 | G4: =F4+1 -> 3 | H4: =G4+1 -> 4 | I4: =H4+1 -> 5 | J4: =I4+1 -> 6 | K4: =J4+1 -> 7 | L4: =K4+1 -> 8 | ... AC4: =AB4+1 -> 25
A5: Operations flag | B5: flag | E5: =IF(AND(E$4>=1,E$4<=Inputs!$B$9),1,0) -> 1 | F5: =IF(AND(F$4>=1,F$4<=Inputs!$B$9),1,0) -> 1 | G5: =IF(AND(G$4>=1,G$4<=Inputs!$B$9),1,0) -> 1 | H5: =IF(AND(H$4>=1,H$4<=Inputs!$B$9),1,0) -> 1 | I5: =IF(AND(I$4>=1,I$4<=Inputs!$B$9),1,0) -> 1 | J5: =IF(AND(J$4>=1,J$4<=Inputs!$B$9),1,0) -> 1 | K5: =IF(AND(K$4>=1,K$4<=Inputs!$B$9),1,0) -> 1 | L5: =IF(AND(L$4>=1,L$4<=Inputs!$B$9),1,0) -> 1 | ... AC5: =IF(AND(AC$4>=1,AC$4<=Inputs!$B$9),1,0) -> 1
A6: Senior repayment flag | B6: flag | E6: =IF(AND(E$4>=1,E$4<=Inputs!$B$24),1,0) -> 1 | F6: =IF(AND(F$4>=1,F$4<=Inputs!$B$24),1,0) -> 1 | G6: =IF(AND(G$4>=1,G$4<=Inputs!$B$24),1,0) -> 1 | H6: =IF(AND(H$4>=1,H$4<=Inputs!$B$24),1,0) -> 1 | I6: =IF(AND(I$4>=1,I$4<=Inputs!$B$24),1,0) -> 1 | J6: =IF(AND(J$4>=1,J$4<=Inputs!$B$24),1,0) -> 1 | K6: =IF(AND(K$4>=1,K$4<=Inputs!$B$24),1,0) -> 1 | L6: =IF(AND(L$4>=1,L$4<=Inputs!$B$24),1,0) -> 1 | ... AC6: =IF(AND(AC$4>=1,AC$4<=Inputs!$B$24),1,0) -> 0
A7: Mezz repayment flag | B7: flag | E7: =IF(AND(E$4>=1,E$4<=Inputs!$B$30),1,0) -> 1 | F7: =IF(AND(F$4>=1,F$4<=Inputs!$B$30),1,0) -> 1 | G7: =IF(AND(G$4>=1,G$4<=Inputs!$B$30),1,0) -> 1 | H7: =IF(AND(H$4>=1,H$4<=Inputs!$B$30),1,0) -> 1 | I7: =IF(AND(I$4>=1,I$4<=Inputs!$B$30),1,0) -> 1 | J7: =IF(AND(J$4>=1,J$4<=Inputs!$B$30),1,0) -> 1 | K7: =IF(AND(K$4>=1,K$4<=Inputs!$B$30),1,0) -> 1 | L7: =IF(AND(L$4>=1,L$4<=Inputs!$B$30),1,0) -> 1 | ... AC7: =IF(AND(AC$4>=1,AC$4<=Inputs!$B$30),1,0) -> 0
A9: Operations & CFADS
A10: Net generation: P50 | B10: MWh | C10: =SUM(E10:AC10) -> 7428604.8 | E10: =Inputs!$B$5*Inputs!$B$6*8760*(1-Inputs!$B$8)^(E$4-1)*E$5 -> 315360 | F10: =Inputs!$B$5*Inputs!$B$6*8760*(1-Inputs!$B$8)^(F$4-1)*F$5 -> 313783.2 | G10: =Inputs!$B$5*Inputs!$B$6*8760*(1-Inputs!$B$8)^(G$4-1)*G$5 -> 312214.28 | H10: =Inputs!$B$5*Inputs!$B$6*8760*(1-Inputs!$B$8)^(H$4-1)*H$5 -> 310653.21 | I10: =Inputs!$B$5*Inputs!$B$6*8760*(1-Inputs!$B$8)^(I$4-1)*I$5 -> 309099.95 | J10: =Inputs!$B$5*Inputs!$B$6*8760*(1-Inputs!$B$8)^(J$4-1)*J$5 -> 307554.45 | K10: =Inputs!$B$5*Inputs!$B$6*8760*(1-Inputs!$B$8)^(K$4-1)*K$5 -> 306016.67 | L10: =Inputs!$B$5*Inputs!$B$6*8760*(1-Inputs!$B$8)^(L$4-1)*L$5 -> 304486.59 | ... AC10: =Inputs!$B$5*Inputs!$B$6*8760*(1-Inputs!$B$8)^(AC$4-1)*AC$5 -> 279615.05
A11: Net generation: P90 | B11: MWh | C11: =SUM(E11:AC11) -> 6654791.8 | E11: =Inputs!$B$5*Inputs!$B$7*8760*(1-Inputs!$B$8)^(E$4-1)*E$5 -> 282510 | F11: =Inputs!$B$5*Inputs!$B$7*8760*(1-Inputs!$B$8)^(F$4-1)*F$5 -> 281097.45 | G11: =Inputs!$B$5*Inputs!$B$7*8760*(1-Inputs!$B$8)^(G$4-1)*G$5 -> 279691.96 | H11: =Inputs!$B$5*Inputs!$B$7*8760*(1-Inputs!$B$8)^(H$4-1)*H$5 -> 278293.5 | I11: =Inputs!$B$5*Inputs!$B$7*8760*(1-Inputs!$B$8)^(I$4-1)*I$5 -> 276902.04 | J11: =Inputs!$B$5*Inputs!$B$7*8760*(1-Inputs!$B$8)^(J$4-1)*J$5 -> 275517.53 | K11: =Inputs!$B$5*Inputs!$B$7*8760*(1-Inputs!$B$8)^(K$4-1)*K$5 -> 274139.94 | L11: =Inputs!$B$5*Inputs!$B$7*8760*(1-Inputs!$B$8)^(L$4-1)*L$5 -> 272769.24 | ... AC11: =Inputs!$B$5*Inputs!$B$7*8760*(1-Inputs!$B$8)^(AC$4-1)*AC$5 -> 250488.48
A12: PPA tariff | B12: $/MWh | E12: =Inputs!$B$11*(1+Inputs!$B$12)^(E$4-1)*E$5 -> 68 | F12: =Inputs!$B$11*(1+Inputs!$B$12)^(F$4-1)*F$5 -> 69.36 | G12: =Inputs!$B$11*(1+Inputs!$B$12)^(G$4-1)*G$5 -> 70.7472 | H12: =Inputs!$B$11*(1+Inputs!$B$12)^(H$4-1)*H$5 -> 72.162144 | I12: =Inputs!$B$11*(1+Inputs!$B$12)^(I$4-1)*I$5 -> 73.605387 | J12: =Inputs!$B$11*(1+Inputs!$B$12)^(J$4-1)*J$5 -> 75.077495 | K12: =Inputs!$B$11*(1+Inputs!$B$12)^(K$4-1)*K$5 -> 76.579045 | L12: =Inputs!$B$11*(1+Inputs!$B$12)^(L$4-1)*L$5 -> 78.110625 | ... AC12: =Inputs!$B$11*(1+Inputs!$B$12)^(AC$4-1)*AC$5 -> 109.37373
A13: Revenue: P50 | B13: $mm | C13: =SUM(E13:AC13) -> 643.87529 | E13: =E10*E12/10^6 -> 21.44448 | F13: =F10*F12/10^6 -> 21.764003 | G13: =G10*G12/10^6 -> 22.088286 | H13: =H10*H12/10^6 -> 22.417402 | I13: =I10*I12/10^6 -> 22.751421 | J13: =J10*J12/10^6 -> 23.090417 | K13: =K10*K12/10^6 -> 23.434465 | L13: =L10*L12/10^6 -> 23.783638 | ... AC13: =AC10*AC12/10^6 -> 30.582542
A14: Revenue: P90 | B14: $mm | C14: =SUM(E14:AC14) -> 576.80495 | E14: =E11*E12/10^6 -> 19.21068 | F14: =F11*F12/10^6 -> 19.496919 | G14: =G11*G12/10^6 -> 19.787423 | H14: =H11*H12/10^6 -> 20.082256 | I14: =I11*I12/10^6 -> 20.381481 | J14: =J11*J12/10^6 -> 20.685166 | K14: =K11*K12/10^6 -> 20.993374 | L14: =L11*L12/10^6 -> 21.306176 | ... AC14: =AC11*AC12/10^6 -> 27.39686
A15: Operating costs | B15: $mm | C15: =SUM(E15:AC15) -> -92.225963 | E15: =-Inputs!$B$5*1000*Inputs!$B$14*(1+Inputs!$B$15)^(E$4-1)/10^6*E$5 -> -2.7 | F15: =-Inputs!$B$5*1000*Inputs!$B$14*(1+Inputs!$B$15)^(F$4-1)/10^6*F$5 -> -2.7675 | G15: =-Inputs!$B$5*1000*Inputs!$B$14*(1+Inputs!$B$15)^(G$4-1)/10^6*G$5 -> -2.8366875 | H15: =-Inputs!$B$5*1000*Inputs!$B$14*(1+Inputs!$B$15)^(H$4-1)/10^6*H$5 -> -2.9076047 | I15: =-Inputs!$B$5*1000*Inputs!$B$14*(1+Inputs!$B$15)^(I$4-1)/10^6*I$5 -> -2.9802948 | J15: =-Inputs!$B$5*1000*Inputs!$B$14*(1+Inputs!$B$15)^(J$4-1)/10^6*J$5 -> -3.0548022 | K15: =-Inputs!$B$5*1000*Inputs!$B$14*(1+Inputs!$B$15)^(K$4-1)/10^6*K$5 -> -3.1311722 | L15: =-Inputs!$B$5*1000*Inputs!$B$14*(1+Inputs!$B$15)^(L$4-1)/10^6*L$5 -> -3.2094515 | ... AC15: =-Inputs!$B$5*1000*Inputs!$B$14*(1+Inputs!$B$15)^(AC$4-1)/10^6*AC$5 -> -4.8835601
A16: EBITDA: P50 | B16: $mm | C16: =SUM(E16:AC16) -> 551.64933 | E16: =E13+E15 -> 18.74448 | F16: =F13+F15 -> 18.996503 | G16: =G13+G15 -> 19.251599 | H16: =H13+H15 -> 19.509797 | I16: =I13+I15 -> 19.771126 | J16: =J13+J15 -> 20.035615 | K16: =K13+K15 -> 20.303292 | L16: =L13+L15 -> 20.574187 | ... AC16: =AC13+AC15 -> 25.698982
A17: EBITDA: P90 | B17: $mm | C17: =SUM(E17:AC17) -> 484.57898 | E17: =E14+E15 -> 16.51068 | F17: =F14+F15 -> 16.729419 | G17: =G14+G15 -> 16.950736 | H17: =H14+H15 -> 17.174651 | I17: =I14+I15 -> 17.401187 | J17: =J14+J15 -> 17.630363 | K17: =K14+K15 -> 17.862202 | L17: =L14+L15 -> 18.096724 | ... AC17: =AC14+AC15 -> 22.5133
A18: Tax depreciation | B18: $mm | C18: =SUM(E18:AC18) -> 175 | E18: =IF(E$4<=Inputs!$B$22,Inputs!$B$19/Inputs!$B$22,0)*E$5 -> 8.75 | F18: =IF(F$4<=Inputs!$B$22,Inputs!$B$19/Inputs!$B$22,0)*F$5 -> 8.75 | G18: =IF(G$4<=Inputs!$B$22,Inputs!$B$19/Inputs!$B$22,0)*G$5 -> 8.75 | H18: =IF(H$4<=Inputs!$B$22,Inputs!$B$19/Inputs!$B$22,0)*H$5 -> 8.75 | I18: =IF(I$4<=Inputs!$B$22,Inputs!$B$19/Inputs!$B$22,0)*I$5 -> 8.75 | J18: =IF(J$4<=Inputs!$B$22,Inputs!$B$19/Inputs!$B$22,0)*J$5 -> 8.75 | K18: =IF(K$4<=Inputs!$B$22,Inputs!$B$19/Inputs!$B$22,0)*K$5 -> 8.75 | L18: =IF(L$4<=Inputs!$B$22,Inputs!$B$19/Inputs!$B$22,0)*L$5 -> 8.75 | ... AC18: =IF(AC$4<=Inputs!$B$22,Inputs!$B$19/Inputs!$B$22,0)*AC$5 -> 0
A19: Cash tax: P50 | B19: $mm | C19: =SUM(E19:AC19) -> -94.162332 | E19: =-MAX(0,E16-E18)*Inputs!$B$21 -> -2.49862 | F19: =-MAX(0,F16-F18)*Inputs!$B$21 -> -2.5616257 | G19: =-MAX(0,G16-G18)*Inputs!$B$21 -> -2.6253997 | H19: =-MAX(0,H16-H18)*Inputs!$B$21 -> -2.6899493 | I19: =-MAX(0,I16-I18)*Inputs!$B$21 -> -2.7552816 | J19: =-MAX(0,J16-J18)*Inputs!$B$21 -> -2.8214038 | K19: =-MAX(0,K16-K18)*Inputs!$B$21 -> -2.8883231 | L19: =-MAX(0,L16-L18)*Inputs!$B$21 -> -2.9560466 | ... AC19: =-MAX(0,AC16-AC18)*Inputs!$B$21 -> -6.4247455
A20: Cash tax: P90 | B20: $mm | C20: =SUM(E20:AC20) -> -77.394746 | E20: =-MAX(0,E17-E18)*Inputs!$B$21 -> -1.94017 | F20: =-MAX(0,F17-F18)*Inputs!$B$21 -> -1.9948548 | G20: =-MAX(0,G17-G18)*Inputs!$B$21 -> -2.0501839 | H20: =-MAX(0,H17-H18)*Inputs!$B$21 -> -2.1061628 | I20: =-MAX(0,I17-I18)*Inputs!$B$21 -> -2.1627967 | J20: =-MAX(0,J17-J18)*Inputs!$B$21 -> -2.2200908 | K20: =-MAX(0,K17-K18)*Inputs!$B$21 -> -2.2780506 | L20: =-MAX(0,L17-L18)*Inputs!$B$21 -> -2.3366811 | ... AC20: =-MAX(0,AC17-AC18)*Inputs!$B$21 -> -5.6283251
A21: CFADS: P50 | B21: $mm | C21: =SUM(E21:AC21) -> 457.48699 | E21: =E16+E19 -> 16.24586 | F21: =F16+F19 -> 16.434877 | G21: =G16+G19 -> 16.626199 | H21: =H16+H19 -> 16.819848 | I21: =I16+I19 -> 17.015845 | J21: =J16+J19 -> 17.214211 | K21: =K16+K19 -> 17.414969 | L21: =L16+L19 -> 17.61814 | ... AC21: =AC16+AC19 -> 19.274236
A22: CFADS: P90 | B22: $mm | C22: =SUM(E22:AC22) -> 407.18424 | E22: =E17+E20 -> 14.57051 | F22: =F17+F20 -> 14.734564 | G22: =G17+G20 -> 14.900552 | H22: =H17+H20 -> 15.068488 | I22: =I17+I20 -> 15.23839 | J22: =J17+J20 -> 15.410273 | K22: =K17+K20 -> 15.584152 | L22: =L17+L20 -> 15.760043 | ... AC22: =AC17+AC20 -> 16.884975
A24: Tranche A: Senior debt sizing (sculpted)
A25: Max DS @ P50 target DSCR | B25: $mm | E25: =E21/Inputs!$B$26*E$6 -> 12.496815 | F25: =F21/Inputs!$B$26*F$6 -> 12.642213 | G25: =G21/Inputs!$B$26*G$6 -> 12.789384 | H25: =H21/Inputs!$B$26*H$6 -> 12.938345 | I25: =I21/Inputs!$B$26*I$6 -> 13.089111 | J25: =J21/Inputs!$B$26*J$6 -> 13.241701 | K25: =K21/Inputs!$B$26*K$6 -> 13.39613 | L25: =L21/Inputs!$B$26*L$6 -> 13.552415 | ... AC25: =AC21/Inputs!$B$26*AC$6 -> 0
A26: Max DS @ P90 target DSCR | B26: $mm | E26: =E22/Inputs!$B$27*E$6 -> 12.142092 | F26: =F22/Inputs!$B$27*F$6 -> 12.278804 | G26: =G22/Inputs!$B$27*G$6 -> 12.417126 | H26: =H22/Inputs!$B$27*H$6 -> 12.557074 | I26: =I22/Inputs!$B$27*I$6 -> 12.698658 | J26: =J22/Inputs!$B$27*J$6 -> 12.841894 | K26: =K22/Inputs!$B$27*K$6 -> 12.986793 | L26: =L22/Inputs!$B$27*L$6 -> 13.133369 | ... AC26: =AC22/Inputs!$B$27*AC$6 -> 0
A27: Target senior DS (lower of) | B27: $mm | C27: =SUM(E27:AC27) -> 240.82921 | E27: =MIN(E25,E26) -> 12.142092 | F27: =MIN(F25,F26) -> 12.278804 | G27: =MIN(G25,G26) -> 12.417126 | H27: =MIN(H25,H26) -> 12.557074 | I27: =MIN(I25,I26) -> 12.698658 | J27: =MIN(J25,J26) -> 12.841894 | K27: =MIN(K25,K26) -> 12.986793 | L27: =MIN(L25,L26) -> 13.133369 | ... AC27: =MIN(AC25,AC26) -> 0
A28: DSCR-based capacity (PV of target DS @ senior rate) | B28: $mm | C28: =NPV(Inputs!$B$25,E27:AC27) -> 136.99149
A29: Gearing-based capacity | B29: $mm | C29: =Inputs!$B$28*Inputs!$B$19 -> 140
A30: Senior debt amount | B30: $mm | C30: =MIN(C28,C29) -> 136.99149
A31: Binding constraint | C31: =IF(C29<C28,"Gearing","DSCR") -> DSCR
A32: DS scaling factor | B32: x | C32: =IF(C28>0,C30/C28,0) -> 1
A33: Senior debt service (sculpted) | B33: $mm | C33: =SUM(E33:AC33) -> 240.82921 | E33: =E27*$C$32 -> 12.142092 | F33: =F27*$C$32 -> 12.278804 | G33: =G27*$C$32 -> 12.417126 | H33: =H27*$C$32 -> 12.557074 | I33: =I27*$C$32 -> 12.698658 | J33: =J27*$C$32 -> 12.841894 | K33: =K27*$C$32 -> 12.986793 | L33: =L27*$C$32 -> 13.133369 | ... AC33: =AC27*$C$32 -> 0
A35: Tranche B: Mezzanine debt sizing (residual on combined DSCR)
A36: Max combined DS @ P50 floor | B36: $mm | E36: =E21/Inputs!$B$32*E$7 -> 14.126835 | F36: =F21/Inputs!$B$32*F$7 -> 14.291197 | G36: =G21/Inputs!$B$32*G$7 -> 14.457564 | H36: =H21/Inputs!$B$32*H$7 -> 14.625955 | I36: =I21/Inputs!$B$32*I$7 -> 14.796387 | J36: =J21/Inputs!$B$32*J$7 -> 14.968879 | K36: =K21/Inputs!$B$32*K$7 -> 15.143452 | L36: =L21/Inputs!$B$32*L$7 -> 15.320122 | ... AC36: =AC21/Inputs!$B$32*AC$7 -> 0
A37: Max combined DS @ P90 floor | B37: $mm | E37: =E22/Inputs!$B$33*E$7 -> 13.876676 | F37: =F22/Inputs!$B$33*F$7 -> 14.032918 | G37: =G22/Inputs!$B$33*G$7 -> 14.191002 | H37: =H22/Inputs!$B$33*H$7 -> 14.350941 | I37: =I22/Inputs!$B$33*I$7 -> 14.512752 | J37: =J22/Inputs!$B$33*J$7 -> 14.67645 | K37: =K22/Inputs!$B$33*K$7 -> 14.842049 | L37: =L22/Inputs!$B$33*L$7 -> 15.009565 | ... AC37: =AC22/Inputs!$B$33*AC$7 -> 0
A38: Target mezz DS (combined less senior) | B38: $mm | C38: =SUM(E38:AC38) -> 34.404173 | E38: =MAX(0,MIN(E36,E37)-E33)*E$7 -> 1.7345845 | F38: =MAX(0,MIN(F36,F37)-F33)*F$7 -> 1.7541148 | G38: =MAX(0,MIN(G36,G37)-G33)*G$7 -> 1.7738752 | H38: =MAX(0,MIN(H36,H37)-H33)*H$7 -> 1.7938677 | I38: =MAX(0,MIN(I36,I37)-I33)*I$7 -> 1.814094 | J38: =MAX(0,MIN(J36,J37)-J33)*J$7 -> 1.8345563 | K38: =MAX(0,MIN(K36,K37)-K33)*K$7 -> 1.8552562 | L38: =MAX(0,MIN(L36,L37)-L33)*L$7 -> 1.8761956 | ... AC38: =MAX(0,MIN(AC36,AC37)-AC33)*AC$7 -> 0
A39: DSCR-based capacity (PV of target DS @ mezz rate) | B39: $mm | C39: =NPV(Inputs!$B$31,E38:AC38) -> 15.247821
A40: Gearing-based capacity (total cap less senior) | B40: $mm | C40: =MAX(0,Inputs!$B$34*Inputs!$B$19-C30) -> 11.75851
A41: Mezzanine debt amount | B41: $mm | C41: =MIN(C39,C40) -> 11.75851
A42: Binding constraint | C42: =IF(C40<C39,"Gearing","DSCR") -> Gearing
A43: DS scaling factor | B43: x | C43: =IF(C39>0,C41/C39,0) -> 0.77116007
A44: Mezz debt service (sculpted) | B44: $mm | C44: =SUM(E44:AC44) -> 26.531124 | E44: =E38*$C$43 -> 1.3376423 | F44: =F38*$C$43 -> 1.3527033 | G44: =G38*$C$43 -> 1.3679417 | H44: =H38*$C$43 -> 1.3833591 | I44: =I38*$C$43 -> 1.3989569 | J44: =J38*$C$43 -> 1.4147365 | K44: =K38*$C$43 -> 1.4306995 | L44: =L38*$C$43 -> 1.4468471 | ... AC44: =AC38*$C$43 -> 0
...
